<!-- Copyright 2021 DeepMind Technologies Limited

     Licensed under the Apache License, Version 2.0 (the "License");
     you may not use this file except in compliance with the License.
     You may obtain a copy of the License at

         http://www.apache.org/licenses/LICENSE-2.0

     Unless required by applicable law or agreed to in writing, software
     distributed under the License is distributed on an "AS IS" BASIS,
     WITHOUT WARRANTIES OR CONDITIONS OF ANY KIND, either express or implied.
     See the License for the specific language governing permissions and
     limitations under the License.
-->

<mujoco model="Pulley">
  <include file="scene.xml"/>

  <!-- <option>
    <flag gravity="disable"/>
  </option> -->

  <statistic center="0 -.3 1" extent="2.5"/>

  <worldbody>

    <flexcomp name="cable" type="grid" count="20 1 1" spacing=".1 0.02 0.02" dim="1"
              radius="0.01" pos="0 0 1.7" rgba="1 0 0 1" >
      <edge equality="true" stiffness="50000" damping="100"/>
    </flexcomp>
    <body name="left" pos="-.7 0 1">
      <joint name="expand_left" type="slide" axis="-1 0 0" range="0 2" damping="20"/>
      <joint name="rotate" type="hinge" axis="0 0 1"/>
      <geom type="cylinder" size=".2 .2" density="1"/>
      <!-- 锚点位置标记 -->
      <body name="left_anchor" pos="0.2 0 0">
        <site  name="left_anchor" size=".01 .01 .01"/>
      </body>
    </body>
    <body name="right" pos=".7 0 1">
      <joint name="expand_right" type="slide" axis="1 0 0" range="0 2" damping="20"/>
      <joint type="hinge" axis="0 0 1"/>
      <geom type="cylinder" size=".2 .2" density="1"/>
      <!-- 锚点位置标记 -->
      <body name="right_anchor" pos="-0.2 0 0">
        <site  name="right_anchor" size=".01 .01 .01"/>
      </body>
    </body>
    <body name="Mid" pos="0 0 1.5" quat="0.707105 0.707108 0 0">
      <joint name="expand_Mid" axis="0 0 1" type="hinge" limited="false" />
      <geom type="cylinder" size=".1 .1" density="1"/>
      <body name="Mid_anchor" pos="-0.1 0 0.1">
        <site  name="Mid_anchor" size=".05 .01 .01"/>
      </body>
    </body>
  </worldbody>

  <equality>
    <weld name="right_boundary" body1="cable_19" body2="right_anchor" relpose="0 0 0 1 0 0 0"/>
    <weld name="left_boundary" body1="cable_0" body2="left_anchor" relpose="0 0 0 1 0 0 0"/>

  </equality>

  <actuator>
    <position name="expand_left" joint="expand_left" ctrlrange="0 2" kp="100"/>
    <position name="expand_right" joint="expand_right" ctrlrange="0 2" kp="100"/>
    <velocity name="rotate" joint="rotate" ctrlrange="0 8"/>
  </actuator>

  <keyframe>
    <key ctrl=".7 .7 8"/>
  </keyframe>
</mujoco>

