<mujoco>
  <compiler autolimits="true"/>

  <asset>
    <texture name="grid" type="2d" builtin="checker" width="512" height="512" rgb1=".1 .2 .3" rgb2=".2 .3 .4"/>
    <material name="grid" texture="grid" texrepeat="1 1" texuniform="true" reflectance=".2"/>
    <mesh name="chasis" scale=".01 .006 .0015"
      vertex=" 9   2   0
              -10  10  10
               9  -2   0
               10  3  -10
               10 -3  -10
              -8   10 -10
              -10 -10  10
              -8  -10 -10
              -5   0   20"/>
  </asset>


  <default>
    <joint damping=".03" actuatorfrcrange="-0.5 0.5"/>
    <default class="wheel">
        <geom type="cylinder" size=".03 .01" rgba=".5 .5 1 1"/>
    </default>
    <default class="decor">
        <site type="box" rgba=".5 1 .5 1"/>
    </default>
</default>


<worldbody>
  <geom type="plane" size="6 6 .01" material="grid"/>

  <body name="pusher1" pos="0 2 .03">

    <freejoint/>
    <geom name="base"
            type="cylinder"
            pos="0 0 0.03"
            size="0.15 0.03"    
            rgba="1.0 0.6 0.2 1"/>

    <geom type="box" pos="0.16 0 0.03" size="0.01 0.14 0.05" rgba="1 1 1 1" />

    <geom name="front wheel" pos="0.12 0 -.015" type="sphere" size=".015" condim="1" priority="1"/>
    

    <body name="left wheel" pos="-.02 .16 0" zaxis="0 1 0">
      <joint name="left"/>
      <geom class="wheel"/>
      <site class="decor" size=".006 .025 .012"/>
      <site class="decor" size=".025 .006 .012"/>
    </body>

    <body name="right wheel" pos="-.02 -.16 0" zaxis="0 1 0">
      <joint name="right"/>
      <geom class="wheel"/>
      <site class="decor" size=".006 .025 .012"/>
      <site class="decor" size=".025 .006 .012"/>
    </body>

  </body>
</worldbody>


<tendon>
  <fixed name="forward">
    <joint joint="left" coef=".5"/>
    <joint joint="right" coef=".5"/>
  </fixed>
  <fixed name="turn">
    <joint joint="left" coef="-.5"/>
    <joint joint="right" coef=".5"/>
  </fixed>
</tendon>

<actuator>
  <motor name="forward" tendon="forward" ctrlrange="-1 1"/>
  <motor name="turn" tendon="turn" ctrlrange="-1 1"/>
</actuator>


<sensor>
    <jointactuatorfrc name="right" joint="right"/>
    <jointactuatorfrc name="left" joint="left"/>
  </sensor>
</mujoco>
